Workbook
Name GroupLabels: Master!$B$2:$B$39
Name KeywordRange: Master!$K$2:$K$186
Name KeywordGroupRange: Master!$L$2:$L$186
Name EntityName: Home!$C$10
Name EntityType: Home!$C$11
Name EntityPAN: Home!$C$12
Name NatureOfBusiness: Home!$C$13
Name EntityAddress: Home!$C$14
Name FYEnd: Home!$F$10
Name PYEnd: Home!$F$11
Name Rounding: Home!$F$12
Name HasTax: Home!$F$13
Name ShowRemun: Home!$F$14
Name SignatoryName: Home!$C$18
Name SignatoryDesignation: Home!$C$19
Name SignatoryPlace: Home!$C$20
Name SignatoryDate: Home!$C$21
Name PreparerFirm: Home!$C$22
Name PreparerMembership: Home!$C$23
Name RoundingFactor: Master!$O$1

Sheet Home
B2: Financial Statement Preparation Tool
B3: ICAI Guidance Note on Financial Statements of Non-Corporate Entities (Division I)
B5: 1. Fill in entity details below.
B6: 2. Go to the Trial Balance sheet, paste/enter your ledgers and confirm the Group for each.
B7: 3. Balance Sheet, Profit & Loss and Notes sheets update automatically.
B9: Entity Details | E9: Reporting
B10: Entity Name | C10: [Enter Entity Name] | E10: Financial Year Ended
B11: Entity Type | C11: Partnership Firm | E11: Previous Year Ended
B12: PAN | E12: Rounding | F12: Actual
B13: Nature of Business | E13: Has own Income-tax liability? (Y/N) | F13: Y
B14: Registered Address | E14: Show Partners' Remuneration line? (Y/N) | F14: Y
B17: Signatory / Preparer
B18: Name of Signatory
B19: Designation | C19: Partner
B20: Place
B21: Date
B22: Auditor / Preparer Firm Name
B23: Membership No.
B26: Go to
B27: Trial Balance -> 'TB'
B28: Balance Sheet -> 'BS'
B29: Profit & Loss -> 'PL'
B30: Notes to Accounts -> 'Notes'

Sheet TB
A1: =Home!$C$10
A2: Trial Balance
A4: GL Code | B4: Ledger Name | C4: Tally Group (optional) | D4: Suggested Group | E4: Group (confirm/override) | F4: CY Debit | G4: CY Credit | H4: PY Debit | I4: PY Credit | J4: Narration
D5: {=IF(B5="","",IFERROR(INDEX(KeywordGroupRange,MATCH(TRUE,ISNUMBER(SEARCH(KeywordRange,B5&" "&C5)),0)),""))} | E5: =IF(B5="","",D5)
D6: {=IF(B6="","",IFERROR(INDEX(KeywordGroupRange,MATCH(TRUE,ISNUMBER(SEARCH(KeywordRange,B6&" "&C6)),0)),""))} | E6: =IF(B6="","",D6)
D7: {=IF(B7="","",IFERROR(INDEX(KeywordGroupRange,MATCH(TRUE,ISNUMBER(SEARCH(KeywordRange,B7&" "&C7)),0)),""))} | E7: =IF(B7="","",D7)
D8: {=IF(B8="","",IFERROR(INDEX(KeywordGroupRange,MATCH(TRUE,ISNUMBER(SEARCH(KeywordRange,B8&" "&C8)),0)),""))} | E8: =IF(B8="","",D8)
D9: {=IF(B9="","",IFERROR(INDEX(KeywordGroupRange,MATCH(TRUE,ISNUMBER(SEARCH(KeywordRange,B9&" "&C9)),0)),""))} | E9: =IF(B9="","",D9)
D10: {=IF(B10="","",IFERROR(INDEX(KeywordGroupRange,MATCH(TRUE,ISNUMBER(SEARCH(KeywordRange,B10&" "&C10)),0)),""))} | E10: =IF(B10="","",D10)
D11: {=IF(B11="","",IFERROR(INDEX(KeywordGroupRange,MATCH(TRUE,ISNUMBER(SEARCH(KeywordRange,B11&" "&C11)),0)),""))} | E11: =IF(B11="","",D11)
D12: {=IF(B12="","",IFERROR(INDEX(KeywordGroupRange,MATCH(TRUE,ISNUMBER(SEARCH(KeywordRange,B12&" "&C12)),0)),""))} | E12: =IF(B12="","",D12)
D13: {=IF(B13="","",IFERROR(INDEX(KeywordGroupRange,MATCH(TRUE,ISNUMBER(SEARCH(KeywordRange,B13&" "&C13)),0)),""))} | E13: =IF(B13="","",D13)
D14: {=IF(B14="","",IFERROR(INDEX(KeywordGroupRange,MATCH(TRUE,ISNUMBER(SEARCH(KeywordRange,B14&" "&C14)),0)),""))} | E14: =IF(B14="","",D14)
D15: {=IF(B15="","",IFERROR(INDEX(KeywordGroupRange,MATCH(TRUE,ISNUMBER(SEARCH(KeywordRange,B15&" "&C15)),0)),""))} | E15: =IF(B15="","",D15)
D16: {=IF(B16="","",IFERROR(INDEX(KeywordGroupRange,MATCH(TRUE,ISNUMBER(SEARCH(KeywordRange,B16&" "&C16)),0)),""))} | E16: =IF(B16="","",D16)
... D504: {=IF(B504="","",IFERROR(INDEX(KeywordGroupRange,MATCH(TRUE,ISNUMBER(SEARCH(KeywordRange,B504&" "&C504)),0)),""))} | E504: =IF(B504="","",D504)
B505: TOTAL | F505: =SUM(F5:F504) | G505: =SUM(G5:G504) | H505: =SUM(H5:H504) | I505: =SUM(I5:I504)
B507: CY Debit - CY Credit (informational; check the Balance Sheet tie-out check for classification errors) | F507: =F505-G505
B508: PY Debit - PY Credit (informational) | F508: =H505-I505

Sheet BS
B1: =Home!$C$10
B2: ="Balance Sheet as at "&TEXT(Home!$F$10,"DD MMMM YYYY")
B3: ="(Rs. in "&Home!$F$12&")"
B5: Particulars | C5: Note | D5: =TEXT(Home!$F$10,"DD MMM YYYY") | E5: =TEXT(Home!$F$11,"DD MMM YYYY")
B6: I. EQUITY AND LIABILITIES
B7: Owners' Fund
B8: =Master!$B$2 | C8: =IFERROR(INDEX(Master!$I$2:$I$39,MATCH(Master!$B$2,Master!$B$2:$B$39,0)),"") | D8: =(SUMIFS(TB!$G$5:$G$504,TB!$E$5:$E$504,Master!$B$2)-SUMIFS(TB!$F$5:$F$504,TB!$E$5:$E$504,Master!$B$2))/RoundingFactor | E8: =(SUMIFS(TB!$I$5:$I$504,TB!$E$5:$E$504,Master!$B$2)-SUMIFS(TB!$H$5:$H$504,TB!$E$5:$E$504,Master!$B$2))/RoundingFactor
B9: =Master!$B$3 | C9: =IFERROR(INDEX(Master!$I$2:$I$39,MATCH(Master!$B$3,Master!$B$2:$B$39,0)),"") | D9: =(SUMIFS(TB!$G$5:$G$504,TB!$E$5:$E$504,Master!$B$3)-SUMIFS(TB!$F$5:$F$504,TB!$E$5:$E$504,Master!$B$3))/RoundingFactor | E9: =(SUMIFS(TB!$I$5:$I$504,TB!$E$5:$E$504,Master!$B$3)-SUMIFS(TB!$H$5:$H$504,TB!$E$5:$E$504,Master!$B$3))/RoundingFactor
B10: Total Owners' Fund | D10: =SUM(D8:D9) | E10: =SUM(E8:E9)
B12: Non-current liabilities
B13: =Master!$B$4 | C13: =IFERROR(INDEX(Master!$I$2:$I$39,MATCH(Master!$B$4,Master!$B$2:$B$39,0)),"") | D13: =(SUMIFS(TB!$G$5:$G$504,TB!$E$5:$E$504,Master!$B$4)-SUMIFS(TB!$F$5:$F$504,TB!$E$5:$E$504,Master!$B$4))/RoundingFactor | E13: =(SUMIFS(TB!$I$5:$I$504,TB!$E$5:$E$504,Master!$B$4)-SUMIFS(TB!$H$5:$H$504,TB!$E$5:$E$504,Master!$B$4))/RoundingFactor
B14: =Master!$B$5 | C14: =IFERROR(INDEX(Master!$I$2:$I$39,MATCH(Master!$B$5,Master!$B$2:$B$39,0)),"") | D14: =(SUMIFS(TB!$G$5:$G$504,TB!$E$5:$E$504,Master!$B$5)-SUMIFS(TB!$F$5:$F$504,TB!$E$5:$E$504,Master!$B$5))/RoundingFactor | E14: =(SUMIFS(TB!$I$5:$I$504,TB!$E$5:$E$504,Master!$B$5)-SUMIFS(TB!$H$5:$H$504,TB!$E$5:$E$504,Master!$B$5))/RoundingFactor
B15: =Master!$B$6 | C15: =IFERROR(INDEX(Master!$I$2:$I$39,MATCH(Master!$B$6,Master!$B$2:$B$39,0)),"") | D15: =(SUMIFS(TB!$G$5:$G$504,TB!$E$5:$E$504,Master!$B$6)-SUMIFS(TB!$F$5:$F$504,TB!$E$5:$E$504,Master!$B$6))/RoundingFactor | E15: =(SUMIFS(TB!$I$5:$I$504,TB!$E$5:$E$504,Master!$B$6)-SUMIFS(TB!$H$5:$H$504,TB!$E$5:$E$504,Master!$B$6))/RoundingFactor
B16: =Master!$B$7 | C16: =IFERROR(INDEX(Master!$I$2:$I$39,MATCH(Master!$B$7,Master!$B$2:$B$39,0)),"") | D16: =(SUMIFS(TB!$G$5:$G$504,TB!$E$5:$E$504,Master!$B$7)-SUMIFS(TB!$F$5:$F$504,TB!$E$5:$E$504,Master!$B$7))/RoundingFactor | E16: =(SUMIFS(TB!$I$5:$I$504,TB!$E$5:$E$504,Master!$B$7)-SUMIFS(TB!$H$5:$H$504,TB!$E$5:$E$504,Master!$B$7))/RoundingFactor
B17: Total Non-current liabilities | D17: =SUM(D13:D16) | E17: =SUM(E13:E16)
B19: Current liabilities
B20: =Master!$B$8 | C20: =IFERROR(INDEX(Master!$I$2:$I$39,MATCH(Master!$B$8,Master!$B$2:$B$39,0)),"") | D20: =(SUMIFS(TB!$G$5:$G$504,TB!$E$5:$E$504,Master!$B$8)-SUMIFS(TB!$F$5:$F$504,TB!$E$5:$E$504,Master!$B$8))/RoundingFactor | E20: =(SUMIFS(TB!$I$5:$I$504,TB!$E$5:$E$504,Master!$B$8)-SUMIFS(TB!$H$5:$H$504,TB!$E$5:$E$504,Master!$B$8))/RoundingFactor
B21: =Master!$B$9 | C21: =IFERROR(INDEX(Master!$I$2:$I$39,MATCH(Master!$B$9,Master!$B$2:$B$39,0)),"") | D21: =(SUMIFS(TB!$G$5:$G$504,TB!$E$5:$E$504,Master!$B$9)-SUMIFS(TB!$F$5:$F$504,TB!$E$5:$E$504,Master!$B$9))/RoundingFactor | E21: =(SUMIFS(TB!$I$5:$I$504,TB!$E$5:$E$504,Master!$B$9)-SUMIFS(TB!$H$5:$H$504,TB!$E$5:$E$504,Master!$B$9))/RoundingFactor
B22: =Master!$B$10 | C22: =IFERROR(INDEX(Master!$I$2:$I$39,MATCH(Master!$B$10,Master!$B$2:$B$39,0)),"") | D22: =(SUMIFS(TB!$G$5:$G$504,TB!$E$5:$E$504,Master!$B$10)-SUMIFS(TB!$F$5:$F$504,TB!$E$5:$E$504,Master!$B$10))/RoundingFactor | E22: =(SUMIFS(TB!$I$5:$I$504,TB!$E$5:$E$504,Master!$B$10)-SUMIFS(TB!$H$5:$H$504,TB!$E$5:$E$504,Master!$B$10))/RoundingFactor
B23: =Master!$B$11 | C23: =IFERROR(INDEX(Master!$I$2:$I$39,MATCH(Master!$B$11,Master!$B$2:$B$39,0)),"") | D23: =(SUMIFS(TB!$G$5:$G$504,TB!$E$5:$E$504,Master!$B$11)-SUMIFS(TB!$F$5:$F$504,TB!$E$5:$E$504,Master!$B$11))/RoundingFactor | E23: =(SUMIFS(TB!$I$5:$I$504,TB!$E$5:$E$504,Master!$B$11)-SUMIFS(TB!$H$5:$H$504,TB!$E$5:$E$504,Master!$B$11))/RoundingFactor
B24: =Master!$B$12 | C24: =IFERROR(INDEX(Master!$I$2:$I$39,MATCH(Master!$B$12,Master!$B$2:$B$39,0)),"") | D24: =(SUMIFS(TB!$G$5:$G$504,TB!$E$5:$E$504,Master!$B$12)-SUMIFS(TB!$F$5:$F$504,TB!$E$5:$E$504,Master!$B$12))/RoundingFactor | E24: =(SUMIFS(TB!$I$5:$I$504,TB!$E$5:$E$504,Master!$B$12)-SUMIFS(TB!$H$5:$H$504,TB!$E$5:$E$504,Master!$B$12))/RoundingFactor
B25: Total Current liabilities | D25: =SUM(D20:D24) | E25: =SUM(E20:E24)
B27: TOTAL EQUITY AND LIABILITIES | D27: =D10+D17+D25 | E27: =E10+E17+E25
B29: II. ASSETS
B30: Non-current assets
B31: =Master!$B$13 | C31: =IFERROR(INDEX(Master!$I$2:$I$39,MATCH(Master!$B$13,Master!$B$2:$B$39,0)),"") | D31: =(SUMIFS(TB!$F$5:$F$504,TB!$E$5:$E$504,Master!$B$13)-SUMIFS(TB!$G$5:$G$504,TB!$E$5:$E$504,Master!$B$13))/RoundingFactor | E31: =(SUMIFS(TB!$H$5:$H$504,TB!$E$5:$E$504,Master!$B$13)-SUMIFS(TB!$I$5:$I$504,TB!$E$5:$E$504,Master!$B$13))/RoundingFactor
B32: =Master!$B$14 | C32: =IFERROR(INDEX(Master!$I$2:$I$39,MATCH(Master!$B$14,Master!$B$2:$B$39,0)),"") | D32: =(SUMIFS(TB!$F$5:$F$504,TB!$E$5:$E$504,Master!$B$14)-SUMIFS(TB!$G$5:$G$504,TB!$E$5:$E$504,Master!$B$14))/RoundingFactor | E32: =(SUMIFS(TB!$H$5:$H$504,TB!$E$5:$E$504,Master!$B$14)-SUMIFS(TB!$I$5:$I$504,TB!$E$5:$E$504,Master!$B$14))/RoundingFactor
B33: =Master!$B$15 | C33: =IFERROR(INDEX(Master!$I$2:$I$39,MATCH(Master!$B$15,Master!$B$2:$B$39,0)),"") | D33: =(SUMIFS(TB!$F$5:$F$504,TB!$E$5:$E$504,Master!$B$15)-SUMIFS(TB!$G$5:$G$504,TB!$E$5:$E$504,Master!$B$15))/RoundingFactor | E33: =(SUMIFS(TB!$H$5:$H$504,TB!$E$5:$E$504,Master!$B$15)-SUMIFS(TB!$I$5:$I$504,TB!$E$5:$E$504,Master!$B$15))/RoundingFactor
B34: =Master!$B$16 | C34: =IFERROR(INDEX(Master!$I$2:$I$39,MATCH(Master!$B$16,Master!$B$2:$B$39,0)),"") | D34: =(SUMIFS(TB!$F$5:$F$504,TB!$E$5:$E$504,Master!$B$16)-SUMIFS(TB!$G$5:$G$504,TB!$E$5:$E$504,Master!$B$16))/RoundingFactor | E34: =(SUMIFS(TB!$H$5:$H$504,TB!$E$5:$E$504,Master!$B$16)-SUMIFS(TB!$I$5:$I$504,TB!$E$5:$E$504,Master!$B$16))/RoundingFactor
B35: =Master!$B$17 | C35: =IFERROR(INDEX(Master!$I$2:$I$39,MATCH(Master!$B$17,Master!$B$2:$B$39,0)),"") | D35: =(SUMIFS(TB!$F$5:$F$504,TB!$E$5:$E$504,Master!$B$17)-SUMIFS(TB!$G$5:$G$504,TB!$E$5:$E$504,Master!$B$17))/RoundingFactor | E35: =(SUMIFS(TB!$H$5:$H$504,TB!$E$5:$E$504,Master!$B$17)-SUMIFS(TB!$I$5:$I$504,TB!$E$5:$E$504,Master!$B$17))/RoundingFactor
B36: =Master!$B$18 | C36: =IFERROR(INDEX(Master!$I$2:$I$39,MATCH(Master!$B$18,Master!$B$2:$B$39,0)),"") | D36: =(SUMIFS(TB!$F$5:$F$504,TB!$E$5:$E$504,Master!$B$18)-SUMIFS(TB!$G$5:$G$504,TB!$E$5:$E$504,Master!$B$18))/RoundingFactor | E36: =(SUMIFS(TB!$H$5:$H$504,TB!$E$5:$E$504,Master!$B$18)-SUMIFS(TB!$I$5:$I$504,TB!$E$5:$E$504,Master!$B$18))/RoundingFactor
B37: =Master!$B$19 | C37: =IFERROR(INDEX(Master!$I$2:$I$39,MATCH(Master!$B$19,Master!$B$2:$B$39,0)),"") | D37: =(SUMIFS(TB!$F$5:$F$504,TB!$E$5:$E$504,Master!$B$19)-SUMIFS(TB!$G$5:$G$504,TB!$E$5:$E$504,Master!$B$19))/RoundingFactor | E37: =(SUMIFS(TB!$H$5:$H$504,TB!$E$5:$E$504,Master!$B$19)-SUMIFS(TB!$I$5:$I$504,TB!$E$5:$E$504,Master!$B$19))/RoundingFactor
B38: =Master!$B$20 | C38: =IFERROR(INDEX(Master!$I$2:$I$39,MATCH(Master!$B$20,Master!$B$2:$B$39,0)),"") | D38: =(SUMIFS(TB!$F$5:$F$504,TB!$E$5:$E$504,Master!$B$20)-SUMIFS(TB!$G$5:$G$504,TB!$E$5:$E$504,Master!$B$20))/RoundingFactor | E38: =(SUMIFS(TB!$H$5:$H$504,TB!$E$5:$E$504,Master!$B$20)-SUMIFS(TB!$I$5:$I$504,TB!$E$5:$E$504,Master!$B$20))/RoundingFactor
B39: =Master!$B$21 | C39: =IFERROR(INDEX(Master!$I$2:$I$39,MATCH(Master!$B$21,Master!$B$2:$B$39,0)),"") | D39: =(SUMIFS(TB!$F$5:$F$504,TB!$E$5:$E$504,Master!$B$21)-SUMIFS(TB!$G$5:$G$504,TB!$E$5:$E$504,Master!$B$21))/RoundingFactor | E39: =(SUMIFS(TB!$H$5:$H$504,TB!$E$5:$E$504,Master!$B$21)-SUMIFS(TB!$I$5:$I$504,TB!$E$5:$E$504,Master!$B$21))/RoundingFactor
B40: Total Non-current assets | D40: =SUM(D31:D39) | E40: =SUM(E31:E39)
B42: Current assets
B43: =Master!$B$22 | C43: =IFERROR(INDEX(Master!$I$2:$I$39,MATCH(Master!$B$22,Master!$B$2:$B$39,0)),"") | D43: =(SUMIFS(TB!$F$5:$F$504,TB!$E$5:$E$504,Master!$B$22)-SUMIFS(TB!$G$5:$G$504,TB!$E$5:$E$504,Master!$B$22))/RoundingFactor | E43: =(SUMIFS(TB!$H$5:$H$504,TB!$E$5:$E$504,Master!$B$22)-SUMIFS(TB!$I$5:$I$504,TB!$E$5:$E$504,Master!$B$22))/RoundingFactor
B44: =Master!$B$23 | C44: =IFERROR(INDEX(Master!$I$2:$I$39,MATCH(Master!$B$23,Master!$B$2:$B$39,0)),"") | D44: =(SUMIFS(TB!$F$5:$F$504,TB!$E$5:$E$504,Master!$B$23)-SUMIFS(TB!$G$5:$G$504,TB!$E$5:$E$504,Master!$B$23))/RoundingFactor | E44: =(SUMIFS(TB!$H$5:$H$504,TB!$E$5:$E$504,Master!$B$23)-SUMIFS(TB!$I$5:$I$504,TB!$E$5:$E$504,Master!$B$23))/RoundingFactor
B45: =Master!$B$24 | C45: =IFERROR(INDEX(Master!$I$2:$I$39,MATCH(Master!$B$24,Master!$B$2:$B$39,0)),"") | D45: =(SUMIFS(TB!$F$5:$F$504,TB!$E$5:$E$504,Master!$B$24)-SUMIFS(TB!$G$5:$G$504,TB!$E$5:$E$504,Master!$B$24))/RoundingFactor | E45: =(SUMIFS(TB!$H$5:$H$504,TB!$E$5:$E$504,Master!$B$24)-SUMIFS(TB!$I$5:$I$504,TB!$E$5:$E$504,Master!$B$24))/RoundingFactor
B46: =Master!$B$25 | C46: =IFERROR(INDEX(Master!$I$2:$I$39,MATCH(Master!$B$25,Master!$B$2:$B$39,0)),"") | D46: =(SUMIFS(TB!$F$5:$F$504,TB!$E$5:$E$504,Master!$B$25)-SUMIFS(TB!$G$5:$G$504,TB!$E$5:$E$504,Master!$B$25))/RoundingFactor | E46: =(SUMIFS(TB!$H$5:$H$504,TB!$E$5:$E$504,Master!$B$25)-SUMIFS(TB!$I$5:$I$504,TB!$E$5:$E$504,Master!$B$25))/RoundingFactor
...

Sheet PL
B1: =Home!$C$10
B2: ="Statement of Profit and Loss for the year ended "&TEXT(Home!$F$10,"DD MMMM YYYY")
B3: ="(Rs. in "&Home!$F$12&")"
B5: Particulars | C5: Note | D5: =TEXT(Home!$F$10,"DD MMM YYYY") | E5: =TEXT(Home!$F$11,"DD MMM YYYY")
B6: INCOME
B7: =Master!$B$28 | C7: =IFERROR(INDEX(Master!$I$2:$I$39,MATCH(Master!$B$28,Master!$B$2:$B$39,0)),"") | D7: =(SUMIFS(TB!$G$5:$G$504,TB!$E$5:$E$504,Master!$B$28)-SUMIFS(TB!$F$5:$F$504,TB!$E$5:$E$504,Master!$B$28))/RoundingFactor | E7: =(SUMIFS(TB!$I$5:$I$504,TB!$E$5:$E$504,Master!$B$28)-SUMIFS(TB!$H$5:$H$504,TB!$E$5:$E$504,Master!$B$28))/RoundingFactor
B8: =Master!$B$29 | C8: =IFERROR(INDEX(Master!$I$2:$I$39,MATCH(Master!$B$29,Master!$B$2:$B$39,0)),"") | D8: =(SUMIFS(TB!$G$5:$G$504,TB!$E$5:$E$504,Master!$B$29)-SUMIFS(TB!$F$5:$F$504,TB!$E$5:$E$504,Master!$B$29))/RoundingFactor | E8: =(SUMIFS(TB!$I$5:$I$504,TB!$E$5:$E$504,Master!$B$29)-SUMIFS(TB!$H$5:$H$504,TB!$E$5:$E$504,Master!$B$29))/RoundingFactor
B9: Total Income | D9: =SUM(D7:D8) | E9: =SUM(E7:E8)
B11: EXPENSES
B12: =Master!$B$30 | C12: =IFERROR(INDEX(Master!$I$2:$I$39,MATCH(Master!$B$30,Master!$B$2:$B$39,0)),"") | D12: =(SUMIFS(TB!$F$5:$F$504,TB!$E$5:$E$504,Master!$B$30)-SUMIFS(TB!$G$5:$G$504,TB!$E$5:$E$504,Master!$B$30))/RoundingFactor | E12: =(SUMIFS(TB!$H$5:$H$504,TB!$E$5:$E$504,Master!$B$30)-SUMIFS(TB!$I$5:$I$504,TB!$E$5:$E$504,Master!$B$30))/RoundingFactor
B13: =Master!$B$31 | C13: =IFERROR(INDEX(Master!$I$2:$I$39,MATCH(Master!$B$31,Master!$B$2:$B$39,0)),"") | D13: =(SUMIFS(TB!$F$5:$F$504,TB!$E$5:$E$504,Master!$B$31)-SUMIFS(TB!$G$5:$G$504,TB!$E$5:$E$504,Master!$B$31))/RoundingFactor | E13: =(SUMIFS(TB!$H$5:$H$504,TB!$E$5:$E$504,Master!$B$31)-SUMIFS(TB!$I$5:$I$504,TB!$E$5:$E$504,Master!$B$31))/RoundingFactor
B14: =Master!$B$32 | C14: =IFERROR(INDEX(Master!$I$2:$I$39,MATCH(Master!$B$32,Master!$B$2:$B$39,0)),"") | D14: =(SUMIFS(TB!$F$5:$F$504,TB!$E$5:$E$504,Master!$B$32)-SUMIFS(TB!$G$5:$G$504,TB!$E$5:$E$504,Master!$B$32))/RoundingFactor | E14: =(SUMIFS(TB!$H$5:$H$504,TB!$E$5:$E$504,Master!$B$32)-SUMIFS(TB!$I$5:$I$504,TB!$E$5:$E$504,Master!$B$32))/RoundingFactor
B15: =Master!$B$33 | C15: =IFERROR(INDEX(Master!$I$2:$I$39,MATCH(Master!$B$33,Master!$B$2:$B$39,0)),"") | D15: =(SUMIFS(TB!$F$5:$F$504,TB!$E$5:$E$504,Master!$B$33)-SUMIFS(TB!$G$5:$G$504,TB!$E$5:$E$504,Master!$B$33))/RoundingFactor | E15: =(SUMIFS(TB!$H$5:$H$504,TB!$E$5:$E$504,Master!$B$33)-SUMIFS(TB!$I$5:$I$504,TB!$E$5:$E$504,Master!$B$33))/RoundingFactor
B16: =Master!$B$34 | C16: =IFERROR(INDEX(Master!$I$2:$I$39,MATCH(Master!$B$34,Master!$B$2:$B$39,0)),"") | D16: =(SUMIFS(TB!$F$5:$F$504,TB!$E$5:$E$504,Master!$B$34)-SUMIFS(TB!$G$5:$G$504,TB!$E$5:$E$504,Master!$B$34))/RoundingFactor | E16: =(SUMIFS(TB!$H$5:$H$504,TB!$E$5:$E$504,Master!$B$34)-SUMIFS(TB!$I$5:$I$504,TB!$E$5:$E$504,Master!$B$34))/RoundingFactor
B17: =Master!$B$35 | C17: =IFERROR(INDEX(Master!$I$2:$I$39,MATCH(Master!$B$35,Master!$B$2:$B$39,0)),"") | D17: =(SUMIFS(TB!$F$5:$F$504,TB!$E$5:$E$504,Master!$B$35)-SUMIFS(TB!$G$5:$G$504,TB!$E$5:$E$504,Master!$B$35))/RoundingFactor | E17: =(SUMIFS(TB!$H$5:$H$504,TB!$E$5:$E$504,Master!$B$35)-SUMIFS(TB!$I$5:$I$504,TB!$E$5:$E$504,Master!$B$35))/RoundingFactor
B18: =Master!$B$36 | C18: =IFERROR(INDEX(Master!$I$2:$I$39,MATCH(Master!$B$36,Master!$B$2:$B$39,0)),"") | D18: =(SUMIFS(TB!$F$5:$F$504,TB!$E$5:$E$504,Master!$B$36)-SUMIFS(TB!$G$5:$G$504,TB!$E$5:$E$504,Master!$B$36))/RoundingFactor | E18: =(SUMIFS(TB!$H$5:$H$504,TB!$E$5:$E$504,Master!$B$36)-SUMIFS(TB!$I$5:$I$504,TB!$E$5:$E$504,Master!$B$36))/RoundingFactor
B19: Total Expenses | D19: =SUM(D12:D18) | E19: =SUM(E12:E18)
B21: =IF(AND(Home!$C$11="Partnership Firm",Home!$F$14="Y"),"Profit before partners' remuneration and tax","Profit before tax") | D21: =D9-D19 | E21: =E9-E19
B22: =IF(AND(Home!$C$11="Partnership Firm",Home!$F$14="Y"),"Less: Remuneration and interest to partners","") | D22: =IF(AND(Home!$C$11="Partnership Firm",Home!$F$14="Y"),(SUMIFS(TB!$F$5:$F$504,TB!$E$5:$E$504,Master!$B$37)-SUMIFS(TB!$G$5:$G$504,TB!$E$5:$E$504,Master!$B$37))/RoundingFactor,0) | E22: =IF(AND(Home!$C$11="Partnership Firm",Home!$F$14="Y"),(SUMIFS(TB!$H$5:$H$504,TB!$E$5:$E$504,Master!$B$37)-SUMIFS(TB!$I$5:$I$504,TB!$E$5:$E$504,Master!$B$37))/RoundingFactor,0)
B23: Profit before tax | D23: =D21-D22 | E23: =E21-E22
B25: =IF(Home!$F$13="Y","TAX EXPENSE","")
B26: =IF(Home!$F$13="Y","Current tax","") | D26: =IF(Home!$F$13="Y",(SUMIFS(TB!$F$5:$F$504,TB!$E$5:$E$504,Master!$B$38)-SUMIFS(TB!$G$5:$G$504,TB!$E$5:$E$504,Master!$B$38))/RoundingFactor,0) | E26: =IF(Home!$F$13="Y",(SUMIFS(TB!$H$5:$H$504,TB!$E$5:$E$504,Master!$B$38)-SUMIFS(TB!$I$5:$I$504,TB!$E$5:$E$504,Master!$B$38))/RoundingFactor,0)
B27: =IF(Home!$F$13="Y","Deferred tax","") | D27: =IF(Home!$F$13="Y",(SUMIFS(TB!$F$5:$F$504,TB!$E$5:$E$504,Master!$B$39)-SUMIFS(TB!$G$5:$G$504,TB!$E$5:$E$504,Master!$B$39))/RoundingFactor,0) | E27: =IF(Home!$F$13="Y",(SUMIFS(TB!$H$5:$H$504,TB!$E$5:$E$504,Master!$B$39)-SUMIFS(TB!$I$5:$I$504,TB!$E$5:$E$504,Master!$B$39))/RoundingFactor,0)
B29: PROFIT FOR THE YEAR | D29: =D23-D26-D27 | E29: =E23-E26-E27

Sheet Notes
B1: =Home!$C$10
B2: Notes forming part of the Financial Statements
B3: ="Tip: filter the Group column on the Trial Balance sheet by a Note's heading below to see the ledger-level detail behind that note."
B5: =IF(Master!$I$2="","","Note "&Master!$I$2&": "&Master!$B$2) | C5: =IF(Master!$I$2="","",TEXT(Home!$F$10,"DD MMM YYYY")) | D5: =IF(Master!$I$2="","",TEXT(Home!$F$11,"DD MMM YYYY"))
B6: =IF(Master!$I$2="","","Total") | C6: =(SUMIFS(TB!$G$5:$G$504,TB!$E$5:$E$504,Master!$B$2)-SUMIFS(TB!$F$5:$F$504,TB!$E$5:$E$504,Master!$B$2))/RoundingFactor | D6: =(SUMIFS(TB!$I$5:$I$504,TB!$E$5:$E$504,Master!$B$2)-SUMIFS(TB!$H$5:$H$504,TB!$E$5:$E$504,Master!$B$2))/RoundingFactor
B8: =IF(Master!$I$3="","","Note "&Master!$I$3&": "&Master!$B$3) | C8: =IF(Master!$I$3="","",TEXT(Home!$F$10,"DD MMM YYYY")) | D8: =IF(Master!$I$3="","",TEXT(Home!$F$11,"DD MMM YYYY"))
B9: =IF(Master!$I$3="","","Total") | C9: =(SUMIFS(TB!$G$5:$G$504,TB!$E$5:$E$504,Master!$B$3)-SUMIFS(TB!$F$5:$F$504,TB!$E$5:$E$504,Master!$B$3))/RoundingFactor | D9: =(SUMIFS(TB!$I$5:$I$504,TB!$E$5:$E$504,Master!$B$3)-SUMIFS(TB!$H$5:$H$504,TB!$E$5:$E$504,Master!$B$3))/RoundingFactor
B11: =IF(Master!$I$4="","","Note "&Master!$I$4&": "&Master!$B$4) | C11: =IF(Master!$I$4="","",TEXT(Home!$F$10,"DD MMM YYYY")) | D11: =IF(Master!$I$4="","",TEXT(Home!$F$11,"DD MMM YYYY"))
B12: =IF(Master!$I$4="","","Total") | C12: =(SUMIFS(TB!$G$5:$G$504,TB!$E$5:$E$504,Master!$B$4)-SUMIFS(TB!$F$5:$F$504,TB!$E$5:$E$504,Master!$B$4))/RoundingFactor | D12: =(SUMIFS(TB!$I$5:$I$504,TB!$E$5:$E$504,Master!$B$4)-SUMIFS(TB!$H$5:$H$504,TB!$E$5:$E$504,Master!$B$4))/RoundingFactor
B14: =IF(Master!$I$5="","","Note "&Master!$I$5&": "&Master!$B$5) | C14: =IF(Master!$I$5="","",TEXT(Home!$F$10,"DD MMM YYYY")) | D14: =IF(Master!$I$5="","",TEXT(Home!$F$11,"DD MMM YYYY"))
B15: =IF(Master!$I$5="","","Total") | C15: =(SUMIFS(TB!$G$5:$G$504,TB!$E$5:$E$504,Master!$B$5)-SUMIFS(TB!$F$5:$F$504,TB!$E$5:$E$504,Master!$B$5))/RoundingFactor | D15: =(SUMIFS(TB!$I$5:$I$504,TB!$E$5:$E$504,Master!$B$5)-SUMIFS(TB!$H$5:$H$504,TB!$E$5:$E$504,Master!$B$5))/RoundingFactor
B17: =IF(Master!$I$6="","","Note "&Master!$I$6&": "&Master!$B$6) | C17: =IF(Master!$I$6="","",TEXT(Home!$F$10,"DD MMM YYYY")) | D17: =IF(Master!$I$6="","",TEXT(Home!$F$11,"DD MMM YYYY"))
B18: =IF(Master!$I$6="","","Total") | C18: =(SUMIFS(TB!$G$5:$G$504,TB!$E$5:$E$504,Master!$B$6)-SUMIFS(TB!$F$5:$F$504,TB!$E$5:$E$504,Master!$B$6))/RoundingFactor | D18: =(SUMIFS(TB!$I$5:$I$504,TB!$E$5:$E$504,Master!$B$6)-SUMIFS(TB!$H$5:$H$504,TB!$E$5:$E$504,Master!$B$6))/RoundingFactor
B20: =IF(Master!$I$7="","","Note "&Master!$I$7&": "&Master!$B$7) | C20: =IF(Master!$I$7="","",TEXT(Home!$F$10,"DD MMM YYYY")) | D20: =IF(Master!$I$7="","",TEXT(Home!$F$11,"DD MMM YYYY"))
B21: =IF(Master!$I$7="","","Total") | C21: =(SUMIFS(TB!$G$5:$G$504,TB!$E$5:$E$504,Master!$B$7)-SUMIFS(TB!$F$5:$F$504,TB!$E$5:$E$504,Master!$B$7))/RoundingFactor | D21: =(SUMIFS(TB!$I$5:$I$504,TB!$E$5:$E$504,Master!$B$7)-SUMIFS(TB!$H$5:$H$504,TB!$E$5:$E$504,Master!$B$7))/RoundingFactor
B23: =IF(Master!$I$8="","","Note "&Master!$I$8&": "&Master!$B$8) | C23: =IF(Master!$I$8="","",TEXT(Home!$F$10,"DD MMM YYYY")) | D23: =IF(Master!$I$8="","",TEXT(Home!$F$11,"DD MMM YYYY"))
B24: =IF(Master!$I$8="","","Total") | C24: =(SUMIFS(TB!$G$5:$G$504,TB!$E$5:$E$504,Master!$B$8)-SUMIFS(TB!$F$5:$F$504,TB!$E$5:$E$504,Master!$B$8))/RoundingFactor | D24: =(SUMIFS(TB!$I$5:$I$504,TB!$E$5:$E$504,Master!$B$8)-SUMIFS(TB!$H$5:$H$504,TB!$E$5:$E$504,Master!$B$8))/RoundingFactor
B26: =IF(Master!$I$9="","","Note "&Master!$I$9&": "&Master!$B$9) | C26: =IF(Master!$I$9="","",TEXT(Home!$F$10,"DD MMM YYYY")) | D26: =IF(Master!$I$9="","",TEXT(Home!$F$11,"DD MMM YYYY"))
B27: =IF(Master!$I$9="","","Total") | C27: =(SUMIFS(TB!$G$5:$G$504,TB!$E$5:$E$504,Master!$B$9)-SUMIFS(TB!$F$5:$F$504,TB!$E$5:$E$504,Master!$B$9))/RoundingFactor | D27: =(SUMIFS(TB!$I$5:$I$504,TB!$E$5:$E$504,Master!$B$9)-SUMIFS(TB!$H$5:$H$504,TB!$E$5:$E$504,Master!$B$9))/RoundingFactor
B29: =IF(Master!$I$10="","","Note "&Master!$I$10&": "&Master!$B$10) | C29: =IF(Master!$I$10="","",TEXT(Home!$F$10,"DD MMM YYYY")) | D29: =IF(Master!$I$10="","",TEXT(Home!$F$11,"DD MMM YYYY"))
B30: =IF(Master!$I$10="","","Total") | C30: =(SUMIFS(TB!$G$5:$G$504,TB!$E$5:$E$504,Master!$B$10)-SUMIFS(TB!$F$5:$F$504,TB!$E$5:$E$504,Master!$B$10))/RoundingFactor | D30: =(SUMIFS(TB!$I$5:$I$504,TB!$E$5:$E$504,Master!$B$10)-SUMIFS(TB!$H$5:$H$504,TB!$E$5:$E$504,Master!$B$10))/RoundingFactor
B32: =IF(Master!$I$11="","","Note "&Master!$I$11&": "&Master!$B$11) | C32: =IF(Master!$I$11="","",TEXT(Home!$F$10,"DD MMM YYYY")) | D32: =IF(Master!$I$11="","",TEXT(Home!$F$11,"DD MMM YYYY"))
B33: =IF(Master!$I$11="","","Total") | C33: =(SUMIFS(TB!$G$5:$G$504,TB!$E$5:$E$504,Master!$B$11)-SUMIFS(TB!$F$5:$F$504,TB!$E$5:$E$504,Master!$B$11))/RoundingFactor | D33: =(SUMIFS(TB!$I$5:$I$504,TB!$E$5:$E$504,Master!$B$11)-SUMIFS(TB!$H$5:$H$504,TB!$E$5:$E$504,Master!$B$11))/RoundingFactor
B35: =IF(Master!$I$12="","","Note "&Master!$I$12&": "&Master!$B$12) | C35: =IF(Master!$I$12="","",TEXT(Home!$F$10,"DD MMM YYYY")) | D35: =IF(Master!$I$12="","",TEXT(Home!$F$11,"DD MMM YYYY"))
B36: =IF(Master!$I$12="","","Total") | C36: =(SUMIFS(TB!$G$5:$G$504,TB!$E$5:$E$504,Master!$B$12)-SUMIFS(TB!$F$5:$F$504,TB!$E$5:$E$504,Master!$B$12))/RoundingFactor | D36: =(SUMIFS(TB!$I$5:$I$504,TB!$E$5:$E$504,Master!$B$12)-SUMIFS(TB!$H$5:$H$504,TB!$E$5:$E$504,Master!$B$12))/RoundingFactor
B38: =IF(Master!$I$13="","","Note "&Master!$I$13&": "&Master!$B$13) | C38: =IF(Master!$I$13="","",TEXT(Home!$F$10,"DD MMM YYYY")) | D38: =IF(Master!$I$13="","",TEXT(Home!$F$11,"DD MMM YYYY"))
B39: =IF(Master!$I$13="","","Total") | C39: =(SUMIFS(TB!$F$5:$F$504,TB!$E$5:$E$504,Master!$B$13)-SUMIFS(TB!$G$5:$G$504,TB!$E$5:$E$504,Master!$B$13))/RoundingFactor | D39: =(SUMIFS(TB!$H$5:$H$504,TB!$E$5:$E$504,Master!$B$13)-SUMIFS(TB!$I$5:$I$504,TB!$E$5:$E$504,Master!$B$13))/RoundingFactor
B41: =IF(Master!$I$14="","","Note "&Master!$I$14&": "&Master!$B$14) | C41: =IF(Master!$I$14="","",TEXT(Home!$F$10,"DD MMM YYYY")) | D41: =IF(Master!$I$14="","",TEXT(Home!$F$11,"DD MMM YYYY"))
B42: =IF(Master!$I$14="","","Total") | C42: =(SUMIFS(TB!$F$5:$F$504,TB!$E$5:$E$504,Master!$B$14)-SUMIFS(TB!$G$5:$G$504,TB!$E$5:$E$504,Master!$B$14))/RoundingFactor | D42: =(SUMIFS(TB!$H$5:$H$504,TB!$E$5:$E$504,Master!$B$14)-SUMIFS(TB!$I$5:$I$504,TB!$E$5:$E$504,Master!$B$14))/RoundingFactor
B44: =IF(Master!$I$15="","","Note "&Master!$I$15&": "&Master!$B$15) | C44: =IF(Master!$I$15="","",TEXT(Home!$F$10,"DD MMM YYYY")) | D44: =IF(Master!$I$15="","",TEXT(Home!$F$11,"DD MMM YYYY"))
B45: =IF(Master!$I$15="","","Total") | C45: =(SUMIFS(TB!$F$5:$F$504,TB!$E$5:$E$504,Master!$B$15)-SUMIFS(TB!$G$5:$G$504,TB!$E$5:$E$504,Master!$B$15))/RoundingFactor | D45: =(SUMIFS(TB!$H$5:$H$504,TB!$E$5:$E$504,Master!$B$15)-SUMIFS(TB!$I$5:$I$504,TB!$E$5:$E$504,Master!$B$15))/RoundingFactor
B47: =IF(Master!$I$16="","","Note "&Master!$I$16&": "&Master!$B$16) | C47: =IF(Master!$I$16="","",TEXT(Home!$F$10,"DD MMM YYYY")) | D47: =IF(Master!$I$16="","",TEXT(Home!$F$11,"DD MMM YYYY"))
B48: =IF(Master!$I$16="","","Total") | C48: =(SUMIFS(TB!$F$5:$F$504,TB!$E$5:$E$504,Master!$B$16)-SUMIFS(TB!$G$5:$G$504,TB!$E$5:$E$504,Master!$B$16))/RoundingFactor | D48: =(SUMIFS(TB!$H$5:$H$504,TB!$E$5:$E$504,Master!$B$16)-SUMIFS(TB!$I$5:$I$504,TB!$E$5:$E$504,Master!$B$16))/RoundingFactor
B50: =IF(Master!$I$17="","","Note "&Master!$I$17&": "&Master!$B$17) | C50: =IF(Master!$I$17="","",TEXT(Home!$F$10,"DD MMM YYYY")) | D50: =IF(Master!$I$17="","",TEXT(Home!$F$11,"DD MMM YYYY"))
B51: =IF(Master!$I$17="","","Total") | C51: =(SUMIFS(TB!$F$5:$F$504,TB!$E$5:$E$504,Master!$B$17)-SUMIFS(TB!$G$5:$G$504,TB!$E$5:$E$504,Master!$B$17))/RoundingFactor | D51: =(SUMIFS(TB!$H$5:$H$504,TB!$E$5:$E$504,Master!$B$17)-SUMIFS(TB!$I$5:$I$504,TB!$E$5:$E$504,Master!$B$17))/RoundingFactor
B53: =IF(Master!$I$18="","","Note "&Master!$I$18&": "&Master!$B$18) | C53: =IF(Master!$I$18="","",TEXT(Home!$F$10,"DD MMM YYYY")) | D53: =IF(Master!$I$18="","",TEXT(Home!$F$11,"DD MMM YYYY"))
B54: =IF(Master!$I$18="","","Total") | C54: =(SUMIFS(TB!$F$5:$F$504,TB!$E$5:$E$504,Master!$B$18)-SUMIFS(TB!$G$5:$G$504,TB!$E$5:$E$504,Master!$B$18))/RoundingFactor | D54: =(SUMIFS(TB!$H$5:$H$504,TB!$E$5:$E$504,Master!$B$18)-SUMIFS(TB!$I$5:$I$504,TB!$E$5:$E$504,Master!$B$18))/RoundingFactor
B56: =IF(Master!$I$19="","","Note "&Master!$I$19&": "&Master!$B$19) | C56: =IF(Master!$I$19="","",TEXT(Home!$F$10,"DD MMM YYYY")) | D56: =IF(Master!$I$19="","",TEXT(Home!$F$11,"DD MMM YYYY"))
B57: =IF(Master!$I$19="","","Total") | C57: =(SUMIFS(TB!$F$5:$F$504,TB!$E$5:$E$504,Master!$B$19)-SUMIFS(TB!$G$5:$G$504,TB!$E$5:$E$504,Master!$B$19))/RoundingFactor | D57: =(SUMIFS(TB!$H$5:$H$504,TB!$E$5:$E$504,Master!$B$19)-SUMIFS(TB!$I$5:$I$504,TB!$E$5:$E$504,Master!$B$19))/RoundingFactor
B59: =IF(Master!$I$20="","","Note "&Master!$I$20&": "&Master!$B$20) | C59: =IF(Master!$I$20="","",TEXT(Home!$F$10,"DD MMM YYYY")) | D59: =IF(Master!$I$20="","",TEXT(Home!$F$11,"DD MMM YYYY"))
...

Sheet Master
A1: Key | B1: Label | C1: Statement | D1: Side | E1: Section | F1: Order | G1: EntityTypes | H1: UsedFlag | I1: NoteNo | K1: Keyword | L1: GroupLabel | N1: RoundingFactor | O1: =CHOOSE(MATCH(Home!$F$12,{"Actual","Hundreds","Thousands","Lakhs","Crores","Millions"},0),1,100,1000,100000,10000000,1000000)
A2: owners_capital | B2: Proprietor's / Partners' Capital Accounts | C2: BS | D2: EquityLiability | E2: Owners' Fund | F2: 10 | H2: =IF(COUNTIF(TB!$E$5:$E$504,B2)>0,1,0) | I2: =IF(H2=1,SUMPRODUCT(($F$2:$F$39<=F2)*($H$2:$H$39=1)),"") | K2: capital account | L2: Proprietor's / Partners' Capital Accounts
A3: reserves_surplus | B3: Reserves and Surplus | C3: BS | D3: EquityLiability | E3: Owners' Fund | F3: 20 | H3: =IF(COUNTIF(TB!$E$5:$E$504,B3)>0,1,0) | I3: =IF(H3=1,SUMPRODUCT(($F$2:$F$39<=F3)*($H$2:$H$39=1)),"") | K3: proprietor | L3: Proprietor's / Partners' Capital Accounts
A4: lt_borrowings | B4: Long-term borrowings | C4: BS | D4: EquityLiability | E4: Non-current liabilities | F4: 30 | H4: =IF(COUNTIF(TB!$E$5:$E$504,B4)>0,1,0) | I4: =IF(H4=1,SUMPRODUCT(($F$2:$F$39<=F4)*($H$2:$H$39=1)),"") | K4: partner | L4: Proprietor's / Partners' Capital Accounts
A5: deferred_tax_liab | B5: Deferred tax liabilities (net) | C5: BS | D5: EquityLiability | E5: Non-current liabilities | F5: 40 | H5: =IF(COUNTIF(TB!$E$5:$E$504,B5)>0,1,0) | I5: =IF(H5=1,SUMPRODUCT(($F$2:$F$39<=F5)*($H$2:$H$39=1)),"") | K5: capital | L5: Proprietor's / Partners' Capital Accounts
A6: other_lt_liabilities | B6: Other long-term liabilities | C6: BS | D6: EquityLiability | E6: Non-current liabilities | F6: 50 | H6: =IF(COUNTIF(TB!$E$5:$E$504,B6)>0,1,0) | I6: =IF(H6=1,SUMPRODUCT(($F$2:$F$39<=F6)*($H$2:$H$39=1)),"") | K6: reserve | L6: Reserves and Surplus
A7: lt_provisions | B7: Long-term provisions | C7: BS | D7: EquityLiability | E7: Non-current liabilities | F7: 60 | H7: =IF(COUNTIF(TB!$E$5:$E$504,B7)>0,1,0) | I7: =IF(H7=1,SUMPRODUCT(($F$2:$F$39<=F7)*($H$2:$H$39=1)),"") | K7: surplus | L7: Reserves and Surplus
A8: st_borrowings | B8: Short-term borrowings | C8: BS | D8: EquityLiability | E8: Current liabilities | F8: 70 | H8: =IF(COUNTIF(TB!$E$5:$E$504,B8)>0,1,0) | I8: =IF(H8=1,SUMPRODUCT(($F$2:$F$39<=F8)*($H$2:$H$39=1)),"") | K8: accumulated profit | L8: Reserves and Surplus
A9: trade_payables_msme | B9: total outstanding dues of micro enterprises and small enterprises | C9: BS | D9: EquityLiability | E9: Current liabilities | F9: 80 | H9: =IF(COUNTIF(TB!$E$5:$E$504,B9)>0,1,0) | I9: =IF(H9=1,SUMPRODUCT(($F$2:$F$39<=F9)*($H$2:$H$39=1)),"") | K9: term loan | L9: Long-term borrowings
A10: trade_payables_others | B10: total outstanding dues of creditors other than micro enterprises and small enterprises | C10: BS | D10: EquityLiability | E10: Current liabilities | F10: 90 | H10: =IF(COUNTIF(TB!$E$5:$E$504,B10)>0,1,0) | I10: =IF(H10=1,SUMPRODUCT(($F$2:$F$39<=F10)*($H$2:$H$39=1)),"") | K10: debenture | L10: Long-term borrowings
A11: other_current_liabilities | B11: Other current liabilities | C11: BS | D11: EquityLiability | E11: Current liabilities | F11: 100 | H11: =IF(COUNTIF(TB!$E$5:$E$504,B11)>0,1,0) | I11: =IF(H11=1,SUMPRODUCT(($F$2:$F$39<=F11)*($H$2:$H$39=1)),"") | K11: vehicle loan | L11: Long-term borrowings
A12: st_provisions | B12: Short-term provisions | C12: BS | D12: EquityLiability | E12: Current liabilities | F12: 110 | H12: =IF(COUNTIF(TB!$E$5:$E$504,B12)>0,1,0) | I12: =IF(H12=1,SUMPRODUCT(($F$2:$F$39<=F12)*($H$2:$H$39=1)),"") | K12: housing loan | L12: Long-term borrowings
A13: ppe | B13: Property, Plant and Equipment | C13: BS | D13: Asset | E13: Non-current assets | F13: 120 | H13: =IF(COUNTIF(TB!$E$5:$E$504,B13)>0,1,0) | I13: =IF(H13=1,SUMPRODUCT(($F$2:$F$39<=F13)*($H$2:$H$39=1)),"") | K13: secured loan | L13: Long-term borrowings
... A36: other_expenses | B36: Other expenses | C36: PL | D36: Expense | E36: Expenses | F36: 380 | H36: =IF(COUNTIF(TB!$E$5:$E$504,B36)>0,1,0) | I36: =IF(H36=1,SUMPRODUCT(($F$2:$F$39<=F36)*($H$2:$H$39=1)),"") | K36: gst payable | L36: Other current liabilities
A37: partners_remuneration | B37: Remuneration and Interest to Partners | C37: PL | D37: Expense | E37: Profit Appropriation | F37: 390 | G37: partnership | H37: =IF(COUNTIF(TB!$E$5:$E$504,B37)>0,1,0) | I37: =IF(H37=1,SUMPRODUCT(($F$2:$F$39<=F37)*($H$2:$H$39=1)),"") | K37: statutory dues | L37: Other current liabilities
A38: current_tax | B38: Current tax | C38: PL | D38: Expense | E38: Tax Expense | F38: 400 | G38: partnership,llp | H38: =IF(COUNTIF(TB!$E$5:$E$504,B38)>0,1,0) | I38: =IF(H38=1,SUMPRODUCT(($F$2:$F$39<=F38)*($H$2:$H$39=1)),"") | K38: advance from customer | L38: Other current liabilities
A39: deferred_tax_pl | B39: Deferred tax | C39: PL | D39: Expense | E39: Tax Expense | F39: 410 | G39: partnership,llp | H39: =IF(COUNTIF(TB!$E$5:$E$504,B39)>0,1,0) | I39: =IF(H39=1,SUMPRODUCT(($F$2:$F$39<=F39)*($H$2:$H$39=1)),"") | K39: unpaid | L39: Other current liabilities
K40: tcs payable | L40: Other current liabilities
K41: pf payable | L41: Other current liabilities
K42: esi payable | L42: Other current liabilities
K43: provision for tax | L43: Short-term provisions
K44: provision for expense | L44: Short-term provisions
K45: provision for bonus | L45: Short-term provisions
K46: provision for audit | L46: Short-term provisions
K47: land | L47: Property, Plant and Equipment
K48: building | L48: Property, Plant and Equipment
K49: plant | L49: Property, Plant and Equipment
K50: machinery | L50: Property, Plant and Equipment
K51: furniture | L51: Property, Plant and Equipment
... K186: deferred tax | L186: Deferred tax
